{
  "cells": [
    {
      "cell_type": "markdown",
      "metadata": {
        "id": "view-in-github",
        "colab_type": "text"
      },
      "source": [
        "<a href=\"https://colab.research.google.com/github/WilliamAGH/python-linguistic-functions/blob/main/lab2.ipynb\" target=\"_parent\"><img src=\"https://colab.research.google.com/assets/colab-badge.svg\" alt=\"Open In Colab\"/></a>"
      ]
    },
    {
      "cell_type": "markdown",
      "metadata": {
        "id": "DTLeMmILlR2M"
      },
      "source": [
        "Double click to edit this cell to add your name and date. After you are done, remove this line.\n",
        "\n",
        "#Lab 2\n",
        "- This part is individual\n",
        "- Write the code for each one of the tests\n",
        "- Make sure to leave the outputs under the code cells after you run them\n",
        "- Turn in both files: this notebook and the Antics.py module\n",
        "\n",
        "**Author**:\n",
        "\n",
        "**Date**:"
      ]
    },
    {
      "cell_type": "markdown",
      "metadata": {
        "id": "09EBCaQ03ufp"
      },
      "source": [
        "## Setup\n",
        "Copy Antics.py to the same folder where you have this notebook and run the following two cells to set up."
      ]
    },
    {
      "cell_type": "code",
      "execution_count": null,
      "metadata": {
        "colab": {
          "background_save": true,
          "base_uri": "https://localhost:8080/"
        },
        "collapsed": true,
        "id": "FrfDMtpPSTvm",
        "outputId": "c135392d-fdd9-49a8-f736-ba1521d152b1"
      },
      "outputs": [
        {
          "name": "stderr",
          "output_type": "stream",
          "text": [
            "ERROR:root:Internal Python error in the inspect module.\n",
            "Below is the traceback from this internal error.\n",
            "\n",
            "ERROR:root:Internal Python error in the inspect module.\n",
            "Below is the traceback from this internal error.\n",
            "\n",
            "ERROR:root:Internal Python error in the inspect module.\n",
            "Below is the traceback from this internal error.\n",
            "\n"
          ]
        },
        {
          "name": "stdout",
          "output_type": "stream",
          "text": [
            "Mounted at /content/gdrive\n",
            "Traceback (most recent call last):\n",
            "  File \"/usr/local/lib/python3.10/dist-packages/IPython/core/interactiveshell.py\", line 3553, in run_code\n",
            "    exec(code_obj, self.user_global_ns, self.user_ns)\n",
            "  File \"<ipython-input-3-d73301d85cab>\", line 4, in <cell line: 4>\n",
            "    get_ipython().run_line_magic('cd', '/content/gdrive/MyDrive/Colab Notebooks/CIS117')\n",
            "  File \"/usr/local/lib/python3.10/dist-packages/IPython/core/interactiveshell.py\", line 2418, in run_line_magic\n",
            "    result = fn(*args, **kwargs)\n",
            "  File \"<decorator-gen-85>\", line 2, in cd\n",
            "  File \"/usr/local/lib/python3.10/dist-packages/IPython/core/magic.py\", line 187, in <lambda>\n",
            "    call = lambda f, *a, **k: f(*a, **k)\n",
            "  File \"/usr/local/lib/python3.10/dist-packages/IPython/core/magics/osm.py\", line 342, in cd\n",
            "    oldcwd = os.getcwd()\n",
            "OSError: [Errno 107] Transport endpoint is not connected\n",
            "\n",
            "During handling of the above exception, another exception occurred:\n",
            "\n",
            "Traceback (most recent call last):\n",
            "  File \"/usr/local/lib/python3.10/dist-packages/IPython/core/interactiveshell.py\", line 2099, in showtraceback\n",
            "    stb = value._render_traceback_()\n",
            "AttributeError: 'OSError' object has no attribute '_render_traceback_'\n",
            "\n",
            "During handling of the above exception, another exception occurred:\n",
            "\n",
            "Traceback (most recent call last):\n",
            "  File \"/usr/local/lib/python3.10/dist-packages/IPython/core/ultratb.py\", line 1101, in get_records\n",
            "    return _fixed_getinnerframes(etb, number_of_lines_of_context, tb_offset)\n",
            "  File \"/usr/local/lib/python3.10/dist-packages/IPython/core/ultratb.py\", line 248, in wrapped\n",
            "    return f(*args, **kwargs)\n",
            "  File \"/usr/local/lib/python3.10/dist-packages/IPython/core/ultratb.py\", line 281, in _fixed_getinnerframes\n",
            "    records = fix_frame_records_filenames(inspect.getinnerframes(etb, context))\n",
            "  File \"/usr/lib/python3.10/inspect.py\", line 1662, in getinnerframes\n",
            "    frameinfo = (tb.tb_frame,) + getframeinfo(tb, context)\n",
            "  File \"/usr/lib/python3.10/inspect.py\", line 1620, in getframeinfo\n",
            "    filename = getsourcefile(frame) or getfile(frame)\n",
            "  File \"/usr/lib/python3.10/inspect.py\", line 829, in getsourcefile\n",
            "    module = getmodule(object, filename)\n",
            "  File \"/usr/lib/python3.10/inspect.py\", line 861, in getmodule\n",
            "    file = getabsfile(object, _filename)\n",
            "  File \"/usr/lib/python3.10/inspect.py\", line 845, in getabsfile\n",
            "    return os.path.normcase(os.path.abspath(_filename))\n",
            "  File \"/usr/lib/python3.10/posixpath.py\", line 384, in abspath\n",
            "    cwd = os.getcwd()\n",
            "OSError: [Errno 107] Transport endpoint is not connected\n",
            "Traceback (most recent call last):\n",
            "  File \"/usr/local/lib/python3.10/dist-packages/IPython/core/interactiveshell.py\", line 3553, in run_code\n",
            "    exec(code_obj, self.user_global_ns, self.user_ns)\n",
            "  File \"<ipython-input-3-d73301d85cab>\", line 4, in <cell line: 4>\n",
            "    get_ipython().run_line_magic('cd', '/content/gdrive/MyDrive/Colab Notebooks/CIS117')\n",
            "  File \"/usr/local/lib/python3.10/dist-packages/IPython/core/interactiveshell.py\", line 2418, in run_line_magic\n",
            "    result = fn(*args, **kwargs)\n",
            "  File \"<decorator-gen-85>\", line 2, in cd\n",
            "  File \"/usr/local/lib/python3.10/dist-packages/IPython/core/magic.py\", line 187, in <lambda>\n",
            "    call = lambda f, *a, **k: f(*a, **k)\n",
            "  File \"/usr/local/lib/python3.10/dist-packages/IPython/core/magics/osm.py\", line 342, in cd\n",
            "    oldcwd = os.getcwd()\n",
            "OSError: [Errno 107] Transport endpoint is not connected\n",
            "\n",
            "During handling of the above exception, another exception occurred:\n",
            "\n",
            "Traceback (most recent call last):\n",
            "  File \"/usr/local/lib/python3.10/dist-packages/IPython/core/interactiveshell.py\", line 2099, in showtraceback\n",
            "    stb = value._render_traceback_()\n",
            "AttributeError: 'OSError' object has no attribute '_render_traceback_'\n",
            "\n",
            "During handling of the above exception, another exception occurred:\n",
            "\n",
            "Traceback (most recent call last):\n",
            "  File \"/usr/local/lib/python3.10/dist-packages/IPython/core/interactiveshell.py\", line 3473, in run_ast_nodes\n",
            "    if (await self.run_code(code, result,  async_=asy)):\n",
            "  File \"/usr/local/lib/python3.10/dist-packages/IPython/core/interactiveshell.py\", line 3575, in run_code\n",
            "    self.showtraceback(running_compiled_code=True)\n",
            "  File \"/usr/local/lib/python3.10/dist-packages/IPython/core/interactiveshell.py\", line 2101, in showtraceback\n",
            "    stb = self.InteractiveTB.structured_traceback(etype,\n",
            "  File \"/usr/local/lib/python3.10/dist-packages/IPython/core/ultratb.py\", line 1367, in structured_traceback\n",
            "    return FormattedTB.structured_traceback(\n",
            "  File \"/usr/local/lib/python3.10/dist-packages/IPython/core/ultratb.py\", line 1267, in structured_traceback\n",
            "    return VerboseTB.structured_traceback(\n",
            "  File \"/usr/local/lib/python3.10/dist-packages/IPython/core/ultratb.py\", line 1124, in structured_traceback\n",
            "    formatted_exception = self.format_exception_as_a_whole(etype, evalue, etb, number_of_lines_of_context,\n",
            "  File \"/usr/local/lib/python3.10/dist-packages/IPython/core/ultratb.py\", line 1082, in format_exception_as_a_whole\n",
            "    last_unique, recursion_repeat = find_recursion(orig_etype, evalue, records)\n",
            "  File \"/usr/local/lib/python3.10/dist-packages/IPython/core/ultratb.py\", line 382, in find_recursion\n",
            "    return len(records), 0\n",
            "TypeError: object of type 'NoneType' has no len()\n",
            "\n",
            "During handling of the above exception, another exception occurred:\n",
            "\n",
            "Traceback (most recent call last):\n",
            "  File \"/usr/local/lib/python3.10/dist-packages/IPython/core/interactiveshell.py\", line 2099, in showtraceback\n",
            "    stb = value._render_traceback_()\n",
            "AttributeError: 'TypeError' object has no attribute '_render_traceback_'\n",
            "\n",
            "During handling of the above exception, another exception occurred:\n",
            "\n",
            "Traceback (most recent call last):\n",
            "  File \"/usr/local/lib/python3.10/dist-packages/IPython/core/ultratb.py\", line 1101, in get_records\n",
            "    return _fixed_getinnerframes(etb, number_of_lines_of_context, tb_offset)\n",
            "  File \"/usr/local/lib/python3.10/dist-packages/IPython/core/ultratb.py\", line 248, in wrapped\n",
            "    return f(*args, **kwargs)\n",
            "  File \"/usr/local/lib/python3.10/dist-packages/IPython/core/ultratb.py\", line 281, in _fixed_getinnerframes\n",
            "    records = fix_frame_records_filenames(inspect.getinnerframes(etb, context))\n",
            "  File \"/usr/lib/python3.10/inspect.py\", line 1662, in getinnerframes\n",
            "    frameinfo = (tb.tb_frame,) + getframeinfo(tb, context)\n",
            "  File \"/usr/lib/python3.10/inspect.py\", line 1620, in getframeinfo\n",
            "    filename = getsourcefile(frame) or getfile(frame)\n",
            "  File \"/usr/lib/python3.10/inspect.py\", line 829, in getsourcefile\n",
            "    module = getmodule(object, filename)\n",
            "  File \"/usr/lib/python3.10/inspect.py\", line 861, in getmodule\n",
            "    file = getabsfile(object, _filename)\n",
            "  File \"/usr/lib/python3.10/inspect.py\", line 845, in getabsfile\n",
            "    return os.path.normcase(os.path.abspath(_filename))\n",
            "  File \"/usr/lib/python3.10/posixpath.py\", line 384, in abspath\n",
            "    cwd = os.getcwd()\n",
            "OSError: [Errno 107] Transport endpoint is not connected\n",
            "Traceback (most recent call last):\n",
            "  File \"/usr/local/lib/python3.10/dist-packages/IPython/core/interactiveshell.py\", line 3553, in run_code\n",
            "    exec(code_obj, self.user_global_ns, self.user_ns)\n",
            "  File \"<ipython-input-3-d73301d85cab>\", line 4, in <cell line: 4>\n",
            "    get_ipython().run_line_magic('cd', '/content/gdrive/MyDrive/Colab Notebooks/CIS117')\n",
            "  File \"/usr/local/lib/python3.10/dist-packages/IPython/core/interactiveshell.py\", line 2418, in run_line_magic\n",
            "    result = fn(*args, **kwargs)\n",
            "  File \"<decorator-gen-85>\", line 2, in cd\n",
            "  File \"/usr/local/lib/python3.10/dist-packages/IPython/core/magic.py\", line 187, in <lambda>\n",
            "    call = lambda f, *a, **k: f(*a, **k)\n",
            "  File \"/usr/local/lib/python3.10/dist-packages/IPython/core/magics/osm.py\", line 342, in cd\n",
            "    oldcwd = os.getcwd()\n",
            "OSError: [Errno 107] Transport endpoint is not connected\n",
            "\n",
            "During handling of the above exception, another exception occurred:\n",
            "\n",
            "Traceback (most recent call last):\n",
            "  File \"/usr/local/lib/python3.10/dist-packages/IPython/core/interactiveshell.py\", line 2099, in showtraceback\n",
            "    stb = value._render_traceback_()\n",
            "AttributeError: 'OSError' object has no attribute '_render_traceback_'\n",
            "\n",
            "During handling of the above exception, another exception occurred:\n",
            "\n",
            "Traceback (most recent call last):\n",
            "  File \"/usr/local/lib/python3.10/dist-packages/IPython/core/interactiveshell.py\", line 3473, in run_ast_nodes\n",
            "    if (await self.run_code(code, result,  async_=asy)):\n",
            "  File \"/usr/local/lib/python3.10/dist-packages/IPython/core/interactiveshell.py\", line 3575, in run_code\n",
            "    self.showtraceback(running_compiled_code=True)\n",
            "  File \"/usr/local/lib/python3.10/dist-packages/IPython/core/interactiveshell.py\", line 2101, in showtraceback\n",
            "    stb = self.InteractiveTB.structured_traceback(etype,\n",
            "  File \"/usr/local/lib/python3.10/dist-packages/IPython/core/ultratb.py\", line 1367, in structured_traceback\n",
            "    return FormattedTB.structured_traceback(\n",
            "  File \"/usr/local/lib/python3.10/dist-packages/IPython/core/ultratb.py\", line 1267, in structured_traceback\n",
            "    return VerboseTB.structured_traceback(\n",
            "  File \"/usr/local/lib/python3.10/dist-packages/IPython/core/ultratb.py\", line 1124, in structured_traceback\n",
            "    formatted_exception = self.format_exception_as_a_whole(etype, evalue, etb, number_of_lines_of_context,\n",
            "  File \"/usr/local/lib/python3.10/dist-packages/IPython/core/ultratb.py\", line 1082, in format_exception_as_a_whole\n",
            "    last_unique, recursion_repeat = find_recursion(orig_etype, evalue, records)\n",
            "  File \"/usr/local/lib/python3.10/dist-packages/IPython/core/ultratb.py\", line 382, in find_recursion\n",
            "    return len(records), 0\n",
            "TypeError: object of type 'NoneType' has no len()\n",
            "\n",
            "During handling of the above exception, another exception occurred:\n",
            "\n",
            "Traceback (most recent call last):\n",
            "  File \"/usr/local/lib/python3.10/dist-packages/IPython/core/interactiveshell.py\", line 2099, in showtraceback\n",
            "    stb = value._render_traceback_()\n",
            "AttributeError: 'TypeError' object has no attribute '_render_traceback_'\n",
            "\n",
            "During handling of the above exception, another exception occurred:\n",
            "\n",
            "Traceback (most recent call last):\n",
            "  File \"/usr/local/lib/python3.10/dist-packages/IPython/core/interactiveshell.py\", line 3030, in _run_cell\n",
            "    return runner(coro)\n",
            "  File \"/usr/local/lib/python3.10/dist-packages/IPython/core/async_helpers.py\", line 78, in _pseudo_sync_runner\n",
            "    coro.send(None)\n",
            "  File \"/usr/local/lib/python3.10/dist-packages/IPython/core/interactiveshell.py\", line 3257, in run_cell_async\n",
            "    has_raised = await self.run_ast_nodes(code_ast.body, cell_name,\n",
            "  File \"/usr/local/lib/python3.10/dist-packages/IPython/core/interactiveshell.py\", line 3492, in run_ast_nodes\n",
            "    self.showtraceback()\n",
            "  File \"/usr/local/lib/python3.10/dist-packages/IPython/core/interactiveshell.py\", line 2101, in showtraceback\n",
            "    stb = self.InteractiveTB.structured_traceback(etype,\n",
            "  File \"/usr/local/lib/python3.10/dist-packages/IPython/core/ultratb.py\", line 1367, in structured_traceback\n",
            "    return FormattedTB.structured_traceback(\n",
            "  File \"/usr/local/lib/python3.10/dist-packages/IPython/core/ultratb.py\", line 1267, in structured_traceback\n",
            "    return VerboseTB.structured_traceback(\n",
            "  File \"/usr/local/lib/python3.10/dist-packages/IPython/core/ultratb.py\", line 1142, in structured_traceback\n",
            "    formatted_exceptions += self.format_exception_as_a_whole(etype, evalue, etb, lines_of_context,\n",
            "  File \"/usr/local/lib/python3.10/dist-packages/IPython/core/ultratb.py\", line 1082, in format_exception_as_a_whole\n",
            "    last_unique, recursion_repeat = find_recursion(orig_etype, evalue, records)\n",
            "  File \"/usr/local/lib/python3.10/dist-packages/IPython/core/ultratb.py\", line 382, in find_recursion\n",
            "    return len(records), 0\n",
            "TypeError: object of type 'NoneType' has no len()\n",
            "\n",
            "During handling of the above exception, another exception occurred:\n",
            "\n",
            "Traceback (most recent call last):\n",
            "  File \"/usr/local/lib/python3.10/dist-packages/IPython/core/interactiveshell.py\", line 2099, in showtraceback\n",
            "    stb = value._render_traceback_()\n",
            "AttributeError: 'TypeError' object has no attribute '_render_traceback_'\n",
            "\n",
            "During handling of the above exception, another exception occurred:\n",
            "\n",
            "Traceback (most recent call last):\n",
            "  File \"/usr/local/lib/python3.10/dist-packages/IPython/core/ultratb.py\", line 1101, in get_records\n",
            "    return _fixed_getinnerframes(etb, number_of_lines_of_context, tb_offset)\n",
            "  File \"/usr/local/lib/python3.10/dist-packages/IPython/core/ultratb.py\", line 248, in wrapped\n",
            "    return f(*args, **kwargs)\n",
            "  File \"/usr/local/lib/python3.10/dist-packages/IPython/core/ultratb.py\", line 281, in _fixed_getinnerframes\n",
            "    records = fix_frame_records_filenames(inspect.getinnerframes(etb, context))\n",
            "  File \"/usr/lib/python3.10/inspect.py\", line 1662, in getinnerframes\n",
            "    frameinfo = (tb.tb_frame,) + getframeinfo(tb, context)\n",
            "  File \"/usr/lib/python3.10/inspect.py\", line 1620, in getframeinfo\n",
            "    filename = getsourcefile(frame) or getfile(frame)\n",
            "  File \"/usr/lib/python3.10/inspect.py\", line 829, in getsourcefile\n",
            "    module = getmodule(object, filename)\n",
            "  File \"/usr/lib/python3.10/inspect.py\", line 861, in getmodule\n",
            "    file = getabsfile(object, _filename)\n",
            "  File \"/usr/lib/python3.10/inspect.py\", line 845, in getabsfile\n",
            "    return os.path.normcase(os.path.abspath(_filename))\n",
            "  File \"/usr/lib/python3.10/posixpath.py\", line 384, in abspath\n",
            "    cwd = os.getcwd()\n",
            "OSError: [Errno 107] Transport endpoint is not connected\n"
          ]
        }
      ],
      "source": [
        "# Run this cell to mount your Google Drive\n",
        "from google.colab import drive\n",
        "drive.mount('/content/gdrive', force_remount=True)\n",
        "%cd /content/gdrive/MyDrive/Colab Notebooks/CIS117"
      ]
    },
    {
      "cell_type": "code",
      "execution_count": null,
      "metadata": {
        "colab": {
          "background_save": true,
          "base_uri": "https://localhost:8080/",
          "height": 339
        },
        "collapsed": true,
        "id": "NRxbgO5rSc7M",
        "outputId": "a4d65485-bd72-461a-9647-f4ef93f7148e"
      },
      "outputs": [
        {
          "name": "stderr",
          "output_type": "stream",
          "text": [
            "ERROR:root:Internal Python error in the inspect module.\n",
            "Below is the traceback from this internal error.\n",
            "\n",
            "ERROR:root:Internal Python error in the inspect module.\n",
            "Below is the traceback from this internal error.\n",
            "\n",
            "ERROR:root:Internal Python error in the inspect module.\n",
            "Below is the traceback from this internal error.\n",
            "\n"
          ]
        },
        {
          "name": "stdout",
          "output_type": "stream",
          "text": [
            "Traceback (most recent call last):\n",
            "  File \"/usr/local/lib/python3.10/dist-packages/IPython/core/interactiveshell.py\", line 3553, in run_code\n",
            "    exec(code_obj, self.user_global_ns, self.user_ns)\n",
            "  File \"<ipython-input-3-e6b276c53e82>\", line 2, in <cell line: 2>\n",
            "    import antics as ant\n",
            "  File \"<frozen importlib._bootstrap>\", line 1027, in _find_and_load\n",
            "  File \"<frozen importlib._bootstrap>\", line 1002, in _find_and_load_unlocked\n",
            "  File \"<frozen importlib._bootstrap>\", line 945, in _find_spec\n",
            "  File \"<frozen importlib._bootstrap_external>\", line 1439, in find_spec\n",
            "  File \"<frozen importlib._bootstrap_external>\", line 1408, in _get_spec\n",
            "  File \"<frozen importlib._bootstrap_external>\", line 1366, in _path_importer_cache\n",
            "OSError: [Errno 107] Transport endpoint is not connected\n",
            "\n",
            "During handling of the above exception, another exception occurred:\n",
            "\n",
            "Traceback (most recent call last):\n",
            "  File \"/usr/local/lib/python3.10/dist-packages/IPython/core/interactiveshell.py\", line 2099, in showtraceback\n",
            "    stb = value._render_traceback_()\n",
            "AttributeError: 'OSError' object has no attribute '_render_traceback_'\n",
            "\n",
            "During handling of the above exception, another exception occurred:\n",
            "\n",
            "Traceback (most recent call last):\n",
            "  File \"/usr/local/lib/python3.10/dist-packages/IPython/core/ultratb.py\", line 1101, in get_records\n",
            "    return _fixed_getinnerframes(etb, number_of_lines_of_context, tb_offset)\n",
            "  File \"/usr/local/lib/python3.10/dist-packages/IPython/core/ultratb.py\", line 248, in wrapped\n",
            "    return f(*args, **kwargs)\n",
            "  File \"/usr/local/lib/python3.10/dist-packages/IPython/core/ultratb.py\", line 281, in _fixed_getinnerframes\n",
            "    records = fix_frame_records_filenames(inspect.getinnerframes(etb, context))\n",
            "  File \"/usr/lib/python3.10/inspect.py\", line 1662, in getinnerframes\n",
            "    frameinfo = (tb.tb_frame,) + getframeinfo(tb, context)\n",
            "  File \"/usr/lib/python3.10/inspect.py\", line 1620, in getframeinfo\n",
            "    filename = getsourcefile(frame) or getfile(frame)\n",
            "  File \"/usr/lib/python3.10/inspect.py\", line 829, in getsourcefile\n",
            "    module = getmodule(object, filename)\n",
            "  File \"/usr/lib/python3.10/inspect.py\", line 861, in getmodule\n",
            "    file = getabsfile(object, _filename)\n",
            "  File \"/usr/lib/python3.10/inspect.py\", line 845, in getabsfile\n",
            "    return os.path.normcase(os.path.abspath(_filename))\n",
            "  File \"/usr/lib/python3.10/posixpath.py\", line 384, in abspath\n",
            "    cwd = os.getcwd()\n",
            "OSError: [Errno 107] Transport endpoint is not connected\n",
            "Traceback (most recent call last):\n",
            "  File \"/usr/local/lib/python3.10/dist-packages/IPython/core/interactiveshell.py\", line 3553, in run_code\n",
            "    exec(code_obj, self.user_global_ns, self.user_ns)\n",
            "  File \"<ipython-input-3-e6b276c53e82>\", line 2, in <cell line: 2>\n",
            "    import antics as ant\n",
            "  File \"<frozen importlib._bootstrap>\", line 1027, in _find_and_load\n",
            "  File \"<frozen importlib._bootstrap>\", line 1002, in _find_and_load_unlocked\n",
            "  File \"<frozen importlib._bootstrap>\", line 945, in _find_spec\n",
            "  File \"<frozen importlib._bootstrap_external>\", line 1439, in find_spec\n",
            "  File \"<frozen importlib._bootstrap_external>\", line 1408, in _get_spec\n",
            "  File \"<frozen importlib._bootstrap_external>\", line 1366, in _path_importer_cache\n",
            "OSError: [Errno 107] Transport endpoint is not connected\n",
            "\n",
            "During handling of the above exception, another exception occurred:\n",
            "\n",
            "Traceback (most recent call last):\n",
            "  File \"/usr/local/lib/python3.10/dist-packages/IPython/core/interactiveshell.py\", line 2099, in showtraceback\n",
            "    stb = value._render_traceback_()\n",
            "AttributeError: 'OSError' object has no attribute '_render_traceback_'\n",
            "\n",
            "During handling of the above exception, another exception occurred:\n",
            "\n",
            "Traceback (most recent call last):\n",
            "  File \"/usr/local/lib/python3.10/dist-packages/IPython/core/interactiveshell.py\", line 3473, in run_ast_nodes\n",
            "    if (await self.run_code(code, result,  async_=asy)):\n",
            "  File \"/usr/local/lib/python3.10/dist-packages/IPython/core/interactiveshell.py\", line 3575, in run_code\n",
            "    self.showtraceback(running_compiled_code=True)\n",
            "  File \"/usr/local/lib/python3.10/dist-packages/IPython/core/interactiveshell.py\", line 2101, in showtraceback\n",
            "    stb = self.InteractiveTB.structured_traceback(etype,\n",
            "  File \"/usr/local/lib/python3.10/dist-packages/IPython/core/ultratb.py\", line 1367, in structured_traceback\n",
            "    return FormattedTB.structured_traceback(\n",
            "  File \"/usr/local/lib/python3.10/dist-packages/IPython/core/ultratb.py\", line 1267, in structured_traceback\n",
            "    return VerboseTB.structured_traceback(\n",
            "  File \"/usr/local/lib/python3.10/dist-packages/IPython/core/ultratb.py\", line 1124, in structured_traceback\n",
            "    formatted_exception = self.format_exception_as_a_whole(etype, evalue, etb, number_of_lines_of_context,\n",
            "  File \"/usr/local/lib/python3.10/dist-packages/IPython/core/ultratb.py\", line 1082, in format_exception_as_a_whole\n",
            "    last_unique, recursion_repeat = find_recursion(orig_etype, evalue, records)\n",
            "  File \"/usr/local/lib/python3.10/dist-packages/IPython/core/ultratb.py\", line 382, in find_recursion\n",
            "    return len(records), 0\n",
            "TypeError: object of type 'NoneType' has no len()\n",
            "\n",
            "During handling of the above exception, another exception occurred:\n",
            "\n",
            "Traceback (most recent call last):\n",
            "  File \"/usr/local/lib/python3.10/dist-packages/IPython/core/interactiveshell.py\", line 2099, in showtraceback\n",
            "    stb = value._render_traceback_()\n",
            "AttributeError: 'TypeError' object has no attribute '_render_traceback_'\n",
            "\n",
            "During handling of the above exception, another exception occurred:\n",
            "\n",
            "Traceback (most recent call last):\n",
            "  File \"/usr/local/lib/python3.10/dist-packages/IPython/core/ultratb.py\", line 1101, in get_records\n",
            "    return _fixed_getinnerframes(etb, number_of_lines_of_context, tb_offset)\n",
            "  File \"/usr/local/lib/python3.10/dist-packages/IPython/core/ultratb.py\", line 248, in wrapped\n",
            "    return f(*args, **kwargs)\n",
            "  File \"/usr/local/lib/python3.10/dist-packages/IPython/core/ultratb.py\", line 281, in _fixed_getinnerframes\n",
            "    records = fix_frame_records_filenames(inspect.getinnerframes(etb, context))\n",
            "  File \"/usr/lib/python3.10/inspect.py\", line 1662, in getinnerframes\n",
            "    frameinfo = (tb.tb_frame,) + getframeinfo(tb, context)\n",
            "  File \"/usr/lib/python3.10/inspect.py\", line 1620, in getframeinfo\n",
            "    filename = getsourcefile(frame) or getfile(frame)\n",
            "  File \"/usr/lib/python3.10/inspect.py\", line 829, in getsourcefile\n",
            "    module = getmodule(object, filename)\n",
            "  File \"/usr/lib/python3.10/inspect.py\", line 861, in getmodule\n",
            "    file = getabsfile(object, _filename)\n",
            "  File \"/usr/lib/python3.10/inspect.py\", line 845, in getabsfile\n",
            "    return os.path.normcase(os.path.abspath(_filename))\n",
            "  File \"/usr/lib/python3.10/posixpath.py\", line 384, in abspath\n",
            "    cwd = os.getcwd()\n",
            "OSError: [Errno 107] Transport endpoint is not connected\n",
            "Traceback (most recent call last):\n",
            "  File \"/usr/local/lib/python3.10/dist-packages/IPython/core/interactiveshell.py\", line 3553, in run_code\n",
            "    exec(code_obj, self.user_global_ns, self.user_ns)\n",
            "  File \"<ipython-input-3-e6b276c53e82>\", line 2, in <cell line: 2>\n",
            "    import antics as ant\n",
            "  File \"<frozen importlib._bootstrap>\", line 1027, in _find_and_load\n",
            "  File \"<frozen importlib._bootstrap>\", line 1002, in _find_and_load_unlocked\n",
            "  File \"<frozen importlib._bootstrap>\", line 945, in _find_spec\n",
            "  File \"<frozen importlib._bootstrap_external>\", line 1439, in find_spec\n",
            "  File \"<frozen importlib._bootstrap_external>\", line 1408, in _get_spec\n",
            "  File \"<frozen importlib._bootstrap_external>\", line 1366, in _path_importer_cache\n",
            "OSError: [Errno 107] Transport endpoint is not connected\n",
            "\n",
            "During handling of the above exception, another exception occurred:\n",
            "\n",
            "Traceback (most recent call last):\n",
            "  File \"/usr/local/lib/python3.10/dist-packages/IPython/core/interactiveshell.py\", line 2099, in showtraceback\n",
            "    stb = value._render_traceback_()\n",
            "AttributeError: 'OSError' object has no attribute '_render_traceback_'\n",
            "\n",
            "During handling of the above exception, another exception occurred:\n",
            "\n",
            "Traceback (most recent call last):\n",
            "  File \"/usr/local/lib/python3.10/dist-packages/IPython/core/interactiveshell.py\", line 3473, in run_ast_nodes\n",
            "    if (await self.run_code(code, result,  async_=asy)):\n",
            "  File \"/usr/local/lib/python3.10/dist-packages/IPython/core/interactiveshell.py\", line 3575, in run_code\n",
            "    self.showtraceback(running_compiled_code=True)\n",
            "  File \"/usr/local/lib/python3.10/dist-packages/IPython/core/interactiveshell.py\", line 2101, in showtraceback\n",
            "    stb = self.InteractiveTB.structured_traceback(etype,\n",
            "  File \"/usr/local/lib/python3.10/dist-packages/IPython/core/ultratb.py\", line 1367, in structured_traceback\n",
            "    return FormattedTB.structured_traceback(\n",
            "  File \"/usr/local/lib/python3.10/dist-packages/IPython/core/ultratb.py\", line 1267, in structured_traceback\n",
            "    return VerboseTB.structured_traceback(\n",
            "  File \"/usr/local/lib/python3.10/dist-packages/IPython/core/ultratb.py\", line 1124, in structured_traceback\n",
            "    formatted_exception = self.format_exception_as_a_whole(etype, evalue, etb, number_of_lines_of_context,\n",
            "  File \"/usr/local/lib/python3.10/dist-packages/IPython/core/ultratb.py\", line 1082, in format_exception_as_a_whole\n",
            "    last_unique, recursion_repeat = find_recursion(orig_etype, evalue, records)\n",
            "  File \"/usr/local/lib/python3.10/dist-packages/IPython/core/ultratb.py\", line 382, in find_recursion\n",
            "    return len(records), 0\n",
            "TypeError: object of type 'NoneType' has no len()\n",
            "\n",
            "During handling of the above exception, another exception occurred:\n",
            "\n",
            "Traceback (most recent call last):\n",
            "  File \"/usr/local/lib/python3.10/dist-packages/IPython/core/interactiveshell.py\", line 2099, in showtraceback\n",
            "    stb = value._render_traceback_()\n",
            "AttributeError: 'TypeError' object has no attribute '_render_traceback_'\n",
            "\n",
            "During handling of the above exception, another exception occurred:\n",
            "\n",
            "Traceback (most recent call last):\n",
            "  File \"/usr/local/lib/python3.10/dist-packages/IPython/core/interactiveshell.py\", line 3030, in _run_cell\n",
            "    return runner(coro)\n",
            "  File \"/usr/local/lib/python3.10/dist-packages/IPython/core/async_helpers.py\", line 78, in _pseudo_sync_runner\n",
            "    coro.send(None)\n",
            "  File \"/usr/local/lib/python3.10/dist-packages/IPython/core/interactiveshell.py\", line 3257, in run_cell_async\n",
            "    has_raised = await self.run_ast_nodes(code_ast.body, cell_name,\n",
            "  File \"/usr/local/lib/python3.10/dist-packages/IPython/core/interactiveshell.py\", line 3492, in run_ast_nodes\n",
            "    self.showtraceback()\n",
            "  File \"/usr/local/lib/python3.10/dist-packages/IPython/core/interactiveshell.py\", line 2101, in showtraceback\n",
            "    stb = self.InteractiveTB.structured_traceback(etype,\n",
            "  File \"/usr/local/lib/python3.10/dist-packages/IPython/core/ultratb.py\", line 1367, in structured_traceback\n",
            "    return FormattedTB.structured_traceback(\n",
            "  File \"/usr/local/lib/python3.10/dist-packages/IPython/core/ultratb.py\", line 1267, in structured_traceback\n",
            "    return VerboseTB.structured_traceback(\n",
            "  File \"/usr/local/lib/python3.10/dist-packages/IPython/core/ultratb.py\", line 1142, in structured_traceback\n",
            "    formatted_exceptions += self.format_exception_as_a_whole(etype, evalue, etb, lines_of_context,\n",
            "  File \"/usr/local/lib/python3.10/dist-packages/IPython/core/ultratb.py\", line 1082, in format_exception_as_a_whole\n",
            "    last_unique, recursion_repeat = find_recursion(orig_etype, evalue, records)\n",
            "  File \"/usr/local/lib/python3.10/dist-packages/IPython/core/ultratb.py\", line 382, in find_recursion\n",
            "    return len(records), 0\n",
            "TypeError: object of type 'NoneType' has no len()\n",
            "\n",
            "During handling of the above exception, another exception occurred:\n",
            "\n",
            "Traceback (most recent call last):\n",
            "  File \"/usr/local/lib/python3.10/dist-packages/IPython/core/interactiveshell.py\", line 2099, in showtraceback\n",
            "    stb = value._render_traceback_()\n",
            "AttributeError: 'TypeError' object has no attribute '_render_traceback_'\n",
            "\n",
            "During handling of the above exception, another exception occurred:\n",
            "\n",
            "Traceback (most recent call last):\n",
            "  File \"/usr/local/lib/python3.10/dist-packages/IPython/core/ultratb.py\", line 1101, in get_records\n",
            "    return _fixed_getinnerframes(etb, number_of_lines_of_context, tb_offset)\n",
            "  File \"/usr/local/lib/python3.10/dist-packages/IPython/core/ultratb.py\", line 248, in wrapped\n",
            "    return f(*args, **kwargs)\n",
            "  File \"/usr/local/lib/python3.10/dist-packages/IPython/core/ultratb.py\", line 281, in _fixed_getinnerframes\n",
            "    records = fix_frame_records_filenames(inspect.getinnerframes(etb, context))\n",
            "  File \"/usr/lib/python3.10/inspect.py\", line 1662, in getinnerframes\n",
            "    frameinfo = (tb.tb_frame,) + getframeinfo(tb, context)\n",
            "  File \"/usr/lib/python3.10/inspect.py\", line 1620, in getframeinfo\n",
            "    filename = getsourcefile(frame) or getfile(frame)\n",
            "  File \"/usr/lib/python3.10/inspect.py\", line 829, in getsourcefile\n",
            "    module = getmodule(object, filename)\n",
            "  File \"/usr/lib/python3.10/inspect.py\", line 861, in getmodule\n",
            "    file = getabsfile(object, _filename)\n",
            "  File \"/usr/lib/python3.10/inspect.py\", line 845, in getabsfile\n",
            "    return os.path.normcase(os.path.abspath(_filename))\n",
            "  File \"/usr/lib/python3.10/posixpath.py\", line 384, in abspath\n",
            "    cwd = os.getcwd()\n",
            "OSError: [Errno 107] Transport endpoint is not connected\n"
          ]
        }
      ],
      "source": [
        "# Before you run this cell, make sure you have Antics.py inside the Colab Notebooks folder\n",
        "import Antics as ant"
      ]
    },
    {
      "cell_type": "markdown",
      "metadata": {
        "id": "S8H_mwUc3aEg"
      },
      "source": [
        "# Directions for Testing\n",
        "Write test cases for tests 1-6.\n",
        "Note that I give you an example on how to write the test case on the first test. You are expected to follow the same format on all tests.\n",
        "\n",
        "Leave the outputs on each task."
      ]
    },
    {
      "cell_type": "markdown",
      "metadata": {
        "id": "0bUtg_YrhoK9"
      },
      "source": [
        "**Test 1:** Use the following cell to test the palindrome function that you created in antics.py passing a word that is a palindrome and a word that is not a palindrome like in the example below.\n",
        "\n",
        "**palindrome:** a word or sentence that reads the same backwards\n",
        "\n",
        "An example is provided below. Change it to use your name instead of mine"
      ]
    },
    {
      "cell_type": "code",
      "execution_count": null,
      "metadata": {
        "colab": {
          "base_uri": "https://localhost:8080/"
        },
        "id": "dquJSqkdmk-s",
        "outputId": "8d52958a-8468-4779-fc5a-891e4261ded4"
      },
      "outputs": [
        {
          "name": "stdout",
          "output_type": "stream",
          "text": [
            "hellen is not palindrome\n",
            "anna is palindrome\n"
          ]
        }
      ],
      "source": [
        "print(\"hellen\", \"is\" if ant.palindrome(\"hellen\") else \"is not\", \"palindrome\")\n",
        "print(\"anna\", \"is\" if ant.palindrome(\"anna\") else \"is not\", \"palindrome\")\n"
      ]
    },
    {
      "cell_type": "markdown",
      "metadata": {
        "id": "JMqTVLNSiSjy"
      },
      "source": [
        "**Test 2:** Use the following cell to test the **pangram** function that you defined in antics.py passing a sentence that is a pangram and a sentence that is not a pangram\n",
        "\n",
        "**pangram:** a phrase or sentence containing all 26 letters of the alphabet\n",
        "\n",
        "*Example of a pangram sentence: The quick brown fox jumps over the lazy dog*\n",
        "\n",
        "Make sure to leave the output of your testing below the code cell"
      ]
    },
    {
      "cell_type": "code",
      "execution_count": null,
      "metadata": {
        "id": "6ZHy7IX2n0lh"
      },
      "outputs": [],
      "source": []
    },
    {
      "cell_type": "markdown",
      "metadata": {
        "id": "Y2Dwsybsi9lQ"
      },
      "source": [
        "**Test 3:** Use the following cell to test the **tautogram** function that you defined in antics.py passing a text that is a tautogram and a text that is not a tautogram\n",
        "\n",
        "**tautogram:** a text in which all words start with the same letter\n",
        "\n",
        "*Example of a tautogram sentence: Brilliant, because bacon bites beat bruschetta*\n",
        "\n",
        "Make sure to leave the output of your testing below the code cell"
      ]
    },
    {
      "cell_type": "code",
      "execution_count": null,
      "metadata": {
        "id": "2nRotFvBi79b"
      },
      "outputs": [],
      "source": []
    },
    {
      "cell_type": "markdown",
      "metadata": {
        "id": "CCuPsdhmkGwk"
      },
      "source": [
        "**Test 4:** Use the following cell to test the **isogram** function that you defined in antics.py passing a word that is an isogram and a word that is not an isoogram\n",
        "\n",
        "**isogram:** a word in which no letter of the alphabet occurs more than once\n",
        "\n",
        "*Example of an isogram: demographics*\n",
        "\n",
        "Make sure to leave the output of your testing below the code cell"
      ]
    },
    {
      "cell_type": "code",
      "execution_count": null,
      "metadata": {
        "id": "HMS8akqQpatk"
      },
      "outputs": [],
      "source": []
    },
    {
      "cell_type": "markdown",
      "metadata": {
        "id": "lvCKOdv-ke9X"
      },
      "source": [
        "**Test 5:** Use this cell to test the **abecedarian** function that you defined in antics.py passing a word that is an abecedarian and a word that is not an abecedarian\n",
        "\n",
        "**abecedarian:** a word in which the letters appear in alphabetical order\n",
        "\n",
        "*Examples of abecedarian words: bijoux, biopsy, dimpsy*\n",
        "\n",
        "Make sure to leave the output of your testing below the code cell"
      ]
    },
    {
      "cell_type": "code",
      "execution_count": null,
      "metadata": {
        "id": "yFV8eDfFpbdx"
      },
      "outputs": [],
      "source": []
    },
    {
      "cell_type": "markdown",
      "metadata": {
        "id": "HBNHghIEk-Zz"
      },
      "source": [
        "**Test 6:** Use the following cell to test the **dobloon** function that you defined in antis.py passing a word that is a dobloon and a word that is not a dobloon\n",
        "\n",
        "**dobloon:** a word in which every letter that appears in the word appears exactly twice\n",
        "\n",
        "*Examples of dobloons: murmur, noon, reappear, sees*\n",
        "\n",
        "Make sure to leave the output of your testing below the code cell"
      ]
    },
    {
      "cell_type": "code",
      "execution_count": null,
      "metadata": {
        "id": "NHZb1xYbpbnK"
      },
      "outputs": [],
      "source": []
    },
    {
      "cell_type": "markdown",
      "metadata": {
        "id": "g9sb21KFwAOc"
      },
      "source": [
        "# Submission instructions\n",
        "Make sure you have your name in the first cell.\n",
        "\n",
        "After testing all the functions you implemented in Antics.py by running the cells above, download this notebook and rename it as lab2_YourName.ipynb.\n",
        "\n",
        "On Canvas:\n",
        "\n",
        "*   Share the link to this notebook\n",
        "*   Upload the downloaded lab2_YourName.ipynb\n",
        "*   Upload the Antics.py that you completed with your partner\n",
        "\n"
      ]
    }
  ],
  "metadata": {
    "colab": {
      "provenance": [],
      "include_colab_link": true
    },
    "kernelspec": {
      "display_name": "Python 3",
      "name": "python3"
    },
    "language_info": {
      "name": "python"
    }
  },
  "nbformat": 4,
  "nbformat_minor": 0
}
